{"trial_id": "00", "hyperparameters": {"space": [{"class_name": "Int", "config": {"name": "units", "default": null, "conditions": [], "min_value": 32, "max_value": 256, "step": 32, "sampling": "linear"}}, {"class_name": "Float", "config": {"name": "dropout", "default": 0.2, "conditions": [], "min_value": 0.2, "max_value": 0.5, "step": 0.1, "sampling": "linear"}}, {"class_name": "Float", "config": {"name": "learning_rate", "default": 0.0001, "conditions": [], "min_value": 0.0001, "max_value": 0.01, "step": null, "sampling": "log"}}], "values": {"units": 160, "dropout": 0.30000000000000004, "learning_rate": 0.004436067294554763}}, "metrics": {"metrics": {}}, "score": null, "best_step": 0, "status": "FAILED", "message": "Traceback (most recent call last):\n  File \"d:\\anaconda3\\envs\\tf_gpu\\lib\\site-packages\\keras_tuner\\src\\engine\\base_tuner.py\", line 274, in _try_run_and_update_trial\n    self._run_and_update_trial(trial, *fit_args, **fit_kwargs)\n  File \"d:\\anaconda3\\envs\\tf_gpu\\lib\\site-packages\\keras_tuner\\src\\engine\\base_tuner.py\", line 239, in _run_and_update_trial\n    results = self.run_trial(trial, *fit_args, **fit_kwargs)\n  File \"d:\\anaconda3\\envs\\tf_gpu\\lib\\site-packages\\keras_tuner\\src\\engine\\tuner.py\", line 314, in run_trial\n    obj_value = self._build_and_fit_model(trial, *args, **copied_kwargs)\n  File \"d:\\anaconda3\\envs\\tf_gpu\\lib\\site-packages\\keras_tuner\\src\\engine\\tuner.py\", line 233, in _build_and_fit_model\n    results = self.hypermodel.fit(hp, model, *args, **kwargs)\n  File \"d:\\anaconda3\\envs\\tf_gpu\\lib\\site-packages\\keras_tuner\\src\\engine\\hypermodel.py\", line 149, in fit\n    return model.fit(*args, **kwargs)\n  File \"d:\\anaconda3\\envs\\tf_gpu\\lib\\site-packages\\keras\\utils\\traceback_utils.py\", line 70, in error_handler\n    raise e.with_traceback(filtered_tb) from None\n  File \"d:\\anaconda3\\envs\\tf_gpu\\lib\\site-packages\\tensorflow\\python\\eager\\execute.py\", line 54, in quick_execute\n    tensors = pywrap_tfe.TFE_Py_Execute(ctx._handle, device_name, op_name,\ntensorflow.python.framework.errors_impl.NotFoundError: Graph execution error:\n\nDetected at node 'sequential/resnet50/conv4_block1_1_conv/Conv2D' defined at (most recent call last):\n    File \"d:\\anaconda3\\envs\\tf_gpu\\lib\\runpy.py\", line 196, in _run_module_as_main\n      return _run_code(code, main_globals, None,\n    File \"d:\\anaconda3\\envs\\tf_gpu\\lib\\runpy.py\", line 86, in _run_code\n      exec(code, run_globals)\n    File \"d:\\anaconda3\\envs\\tf_gpu\\lib\\site-packages\\ipykernel_launcher.py\", line 17, in <module>\n      app.launch_new_instance()\n    File \"d:\\anaconda3\\envs\\tf_gpu\\lib\\site-packages\\traitlets\\config\\application.py\", line 1075, in launch_instance\n      app.start()\n    File \"d:\\anaconda3\\envs\\tf_gpu\\lib\\site-packages\\ipykernel\\kernelapp.py\", line 701, in start\n      self.io_loop.start()\n    File \"d:\\anaconda3\\envs\\tf_gpu\\lib\\site-packages\\tornado\\platform\\asyncio.py\", line 205, in start\n      self.asyncio_loop.run_forever()\n    File \"d:\\anaconda3\\envs\\tf_gpu\\lib\\asyncio\\windows_events.py\", line 321, in run_forever\n      super().run_forever()\n    File \"d:\\anaconda3\\envs\\tf_gpu\\lib\\asyncio\\base_events.py\", line 603, in run_forever\n      self._run_once()\n    File \"d:\\anaconda3\\envs\\tf_gpu\\lib\\asyncio\\base_events.py\", line 1909, in _run_once\n      handle._run()\n    File \"d:\\anaconda3\\envs\\tf_gpu\\lib\\asyncio\\events.py\", line 80, in _run\n      self._context.run(self._callback, *self._args)\n    File \"d:\\anaconda3\\envs\\tf_gpu\\lib\\site-packages\\ipykernel\\kernelbase.py\", line 534, in dispatch_queue\n      await self.process_one()\n    File \"d:\\anaconda3\\envs\\tf_gpu\\lib\\site-packages\\ipykernel\\kernelbase.py\", line 523, in process_one\n      await dispatch(*args)\n    File \"d:\\anaconda3\\envs\\tf_gpu\\lib\\site-packages\\ipykernel\\kernelbase.py\", line 429, in dispatch_shell\n      await result\n    File \"d:\\anaconda3\\envs\\tf_gpu\\lib\\site-packages\\ipykernel\\kernelbase.py\", line 767, in execute_request\n      reply_content = await reply_content\n    File \"d:\\anaconda3\\envs\\tf_gpu\\lib\\site-packages\\ipykernel\\ipkernel.py\", line 429, in do_execute\n      res = shell.run_cell(\n    File \"d:\\anaconda3\\envs\\tf_gpu\\lib\\site-packages\\ipykernel\\zmqshell.py\", line 549, in run_cell\n      return super().run_cell(*args, **kwargs)\n    File \"d:\\anaconda3\\envs\\tf_gpu\\lib\\site-packages\\IPython\\core\\interactiveshell.py\", line 3075, in run_cell\n      result = self._run_cell(\n    File \"d:\\anaconda3\\envs\\tf_gpu\\lib\\site-packages\\IPython\\core\\interactiveshell.py\", line 3130, in _run_cell\n      result = runner(coro)\n    File \"d:\\anaconda3\\envs\\tf_gpu\\lib\\site-packages\\IPython\\core\\async_helpers.py\", line 129, in _pseudo_sync_runner\n      coro.send(None)\n    File \"d:\\anaconda3\\envs\\tf_gpu\\lib\\site-packages\\IPython\\core\\interactiveshell.py\", line 3334, in run_cell_async\n      has_raised = await self.run_ast_nodes(code_ast.body, cell_name,\n    File \"d:\\anaconda3\\envs\\tf_gpu\\lib\\site-packages\\IPython\\core\\interactiveshell.py\", line 3517, in run_ast_nodes\n      if await self.run_code(code, result, async_=asy):\n    File \"d:\\anaconda3\\envs\\tf_gpu\\lib\\site-packages\\IPython\\core\\interactiveshell.py\", line 3577, in run_code\n      exec(code_obj, self.user_global_ns, self.user_ns)\n    File \"C:\\Users\\REYES\\AppData\\Local\\Temp\\ipykernel_19048\\251903202.py\", line 1, in <module>\n      tuner.search(\n    File \"d:\\anaconda3\\envs\\tf_gpu\\lib\\site-packages\\keras_tuner\\src\\engine\\base_tuner.py\", line 234, in search\n      self._try_run_and_update_trial(trial, *fit_args, **fit_kwargs)\n    File \"d:\\anaconda3\\envs\\tf_gpu\\lib\\site-packages\\keras_tuner\\src\\engine\\base_tuner.py\", line 274, in _try_run_and_update_trial\n      self._run_and_update_trial(trial, *fit_args, **fit_kwargs)\n    File \"d:\\anaconda3\\envs\\tf_gpu\\lib\\site-packages\\keras_tuner\\src\\engine\\base_tuner.py\", line 239, in _run_and_update_trial\n      results = self.run_trial(trial, *fit_args, **fit_kwargs)\n    File \"d:\\anaconda3\\envs\\tf_gpu\\lib\\site-packages\\keras_tuner\\src\\engine\\tuner.py\", line 314, in run_trial\n      obj_value = self._build_and_fit_model(trial, *args, **copied_kwargs)\n    File \"d:\\anaconda3\\envs\\tf_gpu\\lib\\site-packages\\keras_tuner\\src\\engine\\tuner.py\", line 233, in _build_and_fit_model\n      results = self.hypermodel.fit(hp, model, *args, **kwargs)\n    File \"d:\\anaconda3\\envs\\tf_gpu\\lib\\site-packages\\keras_tuner\\src\\engine\\hypermodel.py\", line 149, in fit\n      return model.fit(*args, **kwargs)\n    File \"d:\\anaconda3\\envs\\tf_gpu\\lib\\site-packages\\keras\\utils\\traceback_utils.py\", line 65, in error_handler\n      return fn(*args, **kwargs)\n    File \"d:\\anaconda3\\envs\\tf_gpu\\lib\\site-packages\\keras\\engine\\training.py\", line 1564, in fit\n      tmp_logs = self.train_function(iterator)\n    File \"d:\\anaconda3\\envs\\tf_gpu\\lib\\site-packages\\keras\\engine\\training.py\", line 1160, in train_function\n      return step_function(self, iterator)\n    File \"d:\\anaconda3\\envs\\tf_gpu\\lib\\site-packages\\keras\\engine\\training.py\", line 1146, in step_function\n      outputs = model.distribute_strategy.run(run_step, args=(data,))\n    File \"d:\\anaconda3\\envs\\tf_gpu\\lib\\site-packages\\keras\\engine\\training.py\", line 1135, in run_step\n      outputs = model.train_step(data)\n    File \"d:\\anaconda3\\envs\\tf_gpu\\lib\\site-packages\\keras\\engine\\training.py\", line 993, in train_step\n      y_pred = self(x, training=True)\n    File \"d:\\anaconda3\\envs\\tf_gpu\\lib\\site-packages\\keras\\utils\\traceback_utils.py\", line 65, in error_handler\n      return fn(*args, **kwargs)\n    File \"d:\\anaconda3\\envs\\tf_gpu\\lib\\site-packages\\keras\\engine\\training.py\", line 557, in __call__\n      return super().__call__(*args, **kwargs)\n    File \"d:\\anaconda3\\envs\\tf_gpu\\lib\\site-packages\\keras\\utils\\traceback_utils.py\", line 65, in error_handler\n      return fn(*args, **kwargs)\n    File \"d:\\anaconda3\\envs\\tf_gpu\\lib\\site-packages\\keras\\engine\\base_layer.py\", line 1097, in __call__\n      outputs = call_fn(inputs, *args, **kwargs)\n    File \"d:\\anaconda3\\envs\\tf_gpu\\lib\\site-packages\\keras\\utils\\traceback_utils.py\", line 96, in error_handler\n      return fn(*args, **kwargs)\n    File \"d:\\anaconda3\\envs\\tf_gpu\\lib\\site-packages\\keras\\engine\\sequential.py\", line 410, in call\n      return super().call(inputs, training=training, mask=mask)\n    File \"d:\\anaconda3\\envs\\tf_gpu\\lib\\site-packages\\keras\\engine\\functional.py\", line 510, in call\n      return self._run_internal_graph(inputs, training=training, mask=mask)\n    File \"d:\\anaconda3\\envs\\tf_gpu\\lib\\site-packages\\keras\\engine\\functional.py\", line 667, in _run_internal_graph\n      outputs = node.layer(*args, **kwargs)\n    File \"d:\\anaconda3\\envs\\tf_gpu\\lib\\site-packages\\keras\\utils\\traceback_utils.py\", line 65, in error_handler\n      return fn(*args, **kwargs)\n    File \"d:\\anaconda3\\envs\\tf_gpu\\lib\\site-packages\\keras\\engine\\training.py\", line 557, in __call__\n      return super().__call__(*args, **kwargs)\n    File \"d:\\anaconda3\\envs\\tf_gpu\\lib\\site-packages\\keras\\utils\\traceback_utils.py\", line 65, in error_handler\n      return fn(*args, **kwargs)\n    File \"d:\\anaconda3\\envs\\tf_gpu\\lib\\site-packages\\keras\\engine\\base_layer.py\", line 1097, in __call__\n      outputs = call_fn(inputs, *args, **kwargs)\n    File \"d:\\anaconda3\\envs\\tf_gpu\\lib\\site-packages\\keras\\utils\\traceback_utils.py\", line 96, in error_handler\n      return fn(*args, **kwargs)\n    File \"d:\\anaconda3\\envs\\tf_gpu\\lib\\site-packages\\keras\\engine\\functional.py\", line 510, in call\n      return self._run_internal_graph(inputs, training=training, mask=mask)\n    File \"d:\\anaconda3\\envs\\tf_gpu\\lib\\site-packages\\keras\\engine\\functional.py\", line 667, in _run_internal_graph\n      outputs = node.layer(*args, **kwargs)\n    File \"d:\\anaconda3\\envs\\tf_gpu\\lib\\site-packages\\keras\\utils\\traceback_utils.py\", line 65, in error_handler\n      return fn(*args, **kwargs)\n    File \"d:\\anaconda3\\envs\\tf_gpu\\lib\\site-packages\\keras\\engine\\base_layer.py\", line 1097, in __call__\n      outputs = call_fn(inputs, *args, **kwargs)\n    File \"d:\\anaconda3\\envs\\tf_gpu\\lib\\site-packages\\keras\\utils\\traceback_utils.py\", line 96, in error_handler\n      return fn(*args, **kwargs)\n    File \"d:\\anaconda3\\envs\\tf_gpu\\lib\\site-packages\\keras\\layers\\convolutional\\base_conv.py\", line 283, in call\n      outputs = self.convolution_op(inputs, self.kernel)\n    File \"d:\\anaconda3\\envs\\tf_gpu\\lib\\site-packages\\keras\\layers\\convolutional\\base_conv.py\", line 255, in convolution_op\n      return tf.nn.convolution(\nNode: 'sequential/resnet50/conv4_block1_1_conv/Conv2D'\nNo algorithm worked!  Error messages:\n  Profiling failure on CUDNN engine 1#TC: RESOURCE_EXHAUSTED: Out of memory while trying to allocate 17304704 bytes.\n  Profiling failure on CUDNN engine 1: RESOURCE_EXHAUSTED: Out of memory while trying to allocate 17304704 bytes.\n  Profiling failure on CUDNN engine 0#TC: RESOURCE_EXHAUSTED: Out of memory while trying to allocate 16777216 bytes.\n  Profiling failure on CUDNN engine 0: RESOURCE_EXHAUSTED: Out of memory while trying to allocate 16777216 bytes.\n  Profiling failure on CUDNN engine 2#TC: RESOURCE_EXHAUSTED: Out of memory while trying to allocate 40435712 bytes.\n  Profiling failure on CUDNN engine 2: RESOURCE_EXHAUSTED: Out of memory while trying to allocate 40435712 bytes.\n\t [[{{node sequential/resnet50/conv4_block1_1_conv/Conv2D}}]] [Op:__inference_train_function_27103]\n"}